2024-12-12 15:24:10,522 INFO    MainThread:12348 [wandb_setup.py:_flush():68] Current SDK version is 0.19.0
2024-12-12 15:24:10,522 INFO    MainThread:12348 [wandb_setup.py:_flush():68] Configure stats pid to 12348
2024-12-12 15:24:10,522 INFO    MainThread:12348 [wandb_setup.py:_flush():68] Loading settings from C:\Users\islam\.config\wandb\settings
2024-12-12 15:24:10,522 INFO    MainThread:12348 [wandb_setup.py:_flush():68] Loading settings from C:\Users\islam\OneDrive\Belgeler\GitHub\GNNportfolio\wandb\settings
2024-12-12 15:24:10,522 INFO    MainThread:12348 [wandb_setup.py:_flush():68] Loading settings from environment variables
2024-12-12 15:24:10,522 INFO    MainThread:12348 [wandb_init.py:_log_setup():528] Logging user logs to C:\Users\islam\OneDrive\Belgeler\GitHub\GNNportfolio\wandb\run-20241212_152410-siwc97wy\logs\debug.log
2024-12-12 15:24:10,523 INFO    MainThread:12348 [wandb_init.py:_log_setup():529] Logging internal logs to C:\Users\islam\OneDrive\Belgeler\GitHub\GNNportfolio\wandb\run-20241212_152410-siwc97wy\logs\debug-internal.log
2024-12-12 15:24:10,523 INFO    MainThread:12348 [wandb_init.py:init():639] calling init triggers
2024-12-12 15:24:10,523 INFO    MainThread:12348 [wandb_init.py:init():645] wandb.init called with sweep_config: {}
config: {}
2024-12-12 15:24:10,523 INFO    MainThread:12348 [wandb_init.py:init():688] starting backend
2024-12-12 15:24:10,523 INFO    MainThread:12348 [wandb_init.py:init():692] sending inform_init request
2024-12-12 15:24:10,558 INFO    MainThread:12348 [backend.py:_multiprocessing_setup():104] multiprocessing start_methods=spawn, using: spawn
2024-12-12 15:24:10,558 INFO    MainThread:12348 [wandb_init.py:init():705] backend started and connected
2024-12-12 15:24:10,560 INFO    MainThread:12348 [wandb_init.py:init():798] updated telemetry
2024-12-12 15:24:10,581 WARNING MsgRouterThr:12348 [router.py:message_loop():75] message_loop has been closed
2024-12-12 15:24:10,606 INFO    MainThread:12348 [wandb_init.py:init():830] communicating run to backend with 90.0 second timeout
2024-12-12 15:24:10,606 ERROR   MainThread:12348 [wandb_init.py:init():1315] error in wandb.init()
Traceback (most recent call last):
  File "C:\Users\islam\AppData\Local\Packages\PythonSoftwareFoundation.Python.3.11_qbz5n2kfra8p0\LocalCache\local-packages\Python311\site-packages\wandb\sdk\wandb_init.py", line 1305, in init
    return wi.init()
           ^^^^^^^^^
  File "C:\Users\islam\AppData\Local\Packages\PythonSoftwareFoundation.Python.3.11_qbz5n2kfra8p0\LocalCache\local-packages\Python311\site-packages\wandb\sdk\wandb_init.py", line 832, in init
    run_init_handle = backend.interface.deliver_run(run)
                      ^^^^^^^^^^^^^^^^^^^^^^^^^^^^^^^^^^
  File "C:\Users\islam\AppData\Local\Packages\PythonSoftwareFoundation.Python.3.11_qbz5n2kfra8p0\LocalCache\local-packages\Python311\site-packages\wandb\sdk\interface\interface.py", line 843, in deliver_run
    return self._deliver_run(run_record)
           ^^^^^^^^^^^^^^^^^^^^^^^^^^^^^
  File "C:\Users\islam\AppData\Local\Packages\PythonSoftwareFoundation.Python.3.11_qbz5n2kfra8p0\LocalCache\local-packages\Python311\site-packages\wandb\sdk\interface\interface_shared.py", line 460, in _deliver_run
    return self._deliver_record(record)
           ^^^^^^^^^^^^^^^^^^^^^^^^^^^^
  File "C:\Users\islam\AppData\Local\Packages\PythonSoftwareFoundation.Python.3.11_qbz5n2kfra8p0\LocalCache\local-packages\Python311\site-packages\wandb\sdk\interface\interface_shared.py", line 455, in _deliver_record
    handle = mailbox._deliver_record(record, interface=self)
             ^^^^^^^^^^^^^^^^^^^^^^^^^^^^^^^^^^^^^^^^^^^^^^^
  File "C:\Users\islam\AppData\Local\Packages\PythonSoftwareFoundation.Python.3.11_qbz5n2kfra8p0\LocalCache\local-packages\Python311\site-packages\wandb\sdk\lib\mailbox.py", line 451, in _deliver_record
    interface._publish(record)
  File "C:\Users\islam\AppData\Local\Packages\PythonSoftwareFoundation.Python.3.11_qbz5n2kfra8p0\LocalCache\local-packages\Python311\site-packages\wandb\sdk\interface\interface_sock.py", line 51, in _publish
    self._sock_client.send_record_publish(record)
  File "C:\Users\islam\AppData\Local\Packages\PythonSoftwareFoundation.Python.3.11_qbz5n2kfra8p0\LocalCache\local-packages\Python311\site-packages\wandb\sdk\lib\sock_client.py", line 222, in send_record_publish
    self.send_server_request(server_req)
  File "C:\Users\islam\AppData\Local\Packages\PythonSoftwareFoundation.Python.3.11_qbz5n2kfra8p0\LocalCache\local-packages\Python311\site-packages\wandb\sdk\lib\sock_client.py", line 154, in send_server_request
    self._send_message(msg)
  File "C:\Users\islam\AppData\Local\Packages\PythonSoftwareFoundation.Python.3.11_qbz5n2kfra8p0\LocalCache\local-packages\Python311\site-packages\wandb\sdk\lib\sock_client.py", line 151, in _send_message
    self._sendall_with_error_handle(header + data)
  File "C:\Users\islam\AppData\Local\Packages\PythonSoftwareFoundation.Python.3.11_qbz5n2kfra8p0\LocalCache\local-packages\Python311\site-packages\wandb\sdk\lib\sock_client.py", line 130, in _sendall_with_error_handle
    sent = self._sock.send(data)
           ^^^^^^^^^^^^^^^^^^^^^
ConnectionResetError: [WinError 10054] Varolan bir baðlantý uzaktaki bir ana bilgisayar tarafýndan zorla kapatýldý
